Workbook
Name UPDATE: 'Data Sheet'!#REF!

Sheet Data Sheet
A1: NAME OF THE COMPANY | B1: DEEPAK NITRITE LTD
A4: Number of shares | B4: =IF(B7>0, B7/B6, 0) -> 13.639292
A5: Face Value | B5: 2
A6: Current Price | B6: 1690.15
A7: Market Capitalization | B7: 23052.45
A13: PROFIT & LOSS
A14: Report Date | B14: 42460 | C14: 42825 | D14: 43190 | E14: 43555 | F14: 43921 | G14: 44286 | H14: 44651 | I14: 45016 | J14: 45382 | K14: 45747
A15: Sales | B15: 1372.93 | C15: 1370.71 | D15: 1651.45 | E15: 2699.92 | F15: 4229.71 | G15: 4359.75 | H15: 6802.19 | I15: 7972.06 | J15: 7681.83 | K15: 8281.93
A16: Raw Material Cost | B16: 832.16 | C16: 849.58 | D16: 1003.71 | E16: 1773.71 | F16: 2315.3 | G16: 2239.55 | H16: 4163.8 | I16: 5495.06 | J16: 5086.96 | K16: 5772.59
A17: Change in Inventory | B17: 6.7 | C17: 25.91 | D17: -10.71 | E17: 153.59 | F17: -25.59 | G17: 10.01 | H17: 96.6 | I17: 191.11 | J17: -102.99 | K17: 24.9
A18: Power and Fuel | B18: 118.15 | C18: 102.44 | D18: 119.88 | E18: 207.33 | F18: 285.19 | G18: 264.74 | H18: 438.61 | I18: 541.93 | J18: 457.12 | K18: 463.52
A19: Other Mfr. Exp | B19: 56.27 | C19: 75.29 | D19: 75.04 | E19: 99.11 | F19: 138.87 | G19: 110.83 | H19: 138.55 | I19: 158.7 | J19: 178.33 | K19: 176.52
A20: Employee Cost | B20: 119.25 | C20: 122.46 | D20: 136.36 | E20: 179.96 | F20: 218.81 | G20: 250.31 | H20: 277.71 | I20: 322.44 | J20: 355.19 | K20: 395.82
A21: Selling and admin | B21: 52.11 | C21: 82.05 | D21: 76.02 | E21: 111.24 | F21: 158.47 | G21: 179.83 | H21: 219.74 | I21: 272.45 | J21: 261.17 | K21: 280.95
A22: Other Expenses | B22: 33.13 | C22: 25.31 | D22: 25.68 | E22: 60.68 | F22: 52.25 | G22: 72.48 | H22: 53.71 | I22: 80.16 | J22: 113.52 | K22: 122.37
A23: Other Income | B23: -0.18 | C23: 79.65 | D23: 6.82 | E23: 10.84 | F23: 28.87 | G23: 19.66 | H23: 41.85 | I23: 46.43 | J23: 155.93 | K23: 83.86
A24: Depreciation | B24: 39.54 | C24: 48.04 | D24: 52.6 | E24: 77.79 | F24: 139.73 | G24: 152.63 | H24: 177.7 | I24: 166.3 | J24: 165.66 | K24: 195.37
A25: Interest | B25: 39.71 | C25: 36.54 | D25: 47.42 | E25: 86.55 | F25: 117.97 | G25: 77.33 | H25: 36.37 | I25: 26.68 | J25: 15.1 | K25: 30.8
... A29: Dividend Amount | B29: 13.96 | C29: 15.68 | D29: 17.73 | E29: 27.28 | F29: 61.38 | G29: 75.02 | H29: 95.48 | I29: 102.3 | J29: 102.3 | K29: 102.3
A38: Quarters
A39: Report Date | B39: 45107 | C39: 45199 | D39: 45291 | E39: 45382 | F39: 45473 | G39: 45565 | H39: 45657 | I39: 45747 | J39: 45838 | K39: 45930
A40: Sales | B40: 1768.34 | C40: 1778.05 | D40: 2009.23 | E40: 2126.21 | F40: 2166.84 | G40: 2032 | H40: 1903.4 | I40: 2179.69 | J40: 1889.88 | K40: 1901.89
A41: Expenses | B41: 1558.59 | C41: 1475.79 | D41: 1704.58 | E41: 1825.09 | F41: 1857.65 | G41: 1734.48 | H41: 1734.86 | I41: 1863.18 | J41: 1700.32 | K41: 1697.62
A42: Other Income | B42: 31.87 | C42: 17.05 | D42: 13.56 | E42: 98.94 | F42: 18.81 | G42: 21.27 | H42: 20.99 | I42: 22.79 | J42: 24.56 | K42: 19.95
A43: Depreciation | B43: 38.08 | C43: 39.43 | D43: 41.69 | E43: 46.46 | F43: 47.45 | G43: 48.46 | H43: 48.22 | I43: 51.25 | J43: 51.25 | K43: 53.25
A44: Interest | B44: 1.81 | C44: 2.68 | D44: 2.93 | E44: 4.41 | F44: 5.75 | G44: 6.3 | H44: 6.11 | I44: 9.34 | J44: 8.13 | K44: 7.94
A45: Profit before tax | B45: 201.73 | C45: 277.2 | D45: 273.59 | E45: 349.19 | F45: 274.8 | G45: 264.03 | H45: 135.2 | I45: 278.71 | J45: 154.74 | K45: 163.03
A46: Tax | B46: 51.83 | C46: 72.12 | D46: 71.54 | E46: 95.34 | F46: 72.27 | G46: 69.83 | H46: 37.07 | I46: 76.21 | J46: 42.49 | K46: 44.28
A47: Net profit | B47: 149.9 | C47: 205.08 | D47: 202.05 | E47: 253.86 | F47: 202.54 | G47: 194.19 | H47: 98.09 | I47: 202.41 | J47: 112.2 | K47: 118.71
A48: Operating Profit | B48: 209.75 | C48: 302.26 | D48: 304.65 | E48: 301.12 | F48: 309.19 | G48: 297.52 | H48: 168.54 | I48: 316.51 | J48: 189.56 | K48: 204.27
A53: BALANCE SHEET
A54: Report Date | B54: 42460 | C54: 42825 | D54: 43190 | E54: 43555 | F54: 43921 | G54: 44286 | H54: 44651 | I54: 45016 | J54: 45382 | K54: 45747
A55: Equity Share Capital | B55: 23.26 | C55: 26.14 | D55: 27.28 | E55: 27.28 | F55: 27.28 | G55: 27.28 | H55: 27.28 | I55: 27.28 | J55: 27.28 | K55: 27.28
A56: Reserves | B56: 449.61 | C56: 688.72 | D56: 894.86 | E56: 1044.31 | F56: 1544.63 | G56: 2319.37 | H56: 3311.16 | I56: 4062.68 | J56: 4769.34 | K56: 5361.39
A57: Borrowings | B57: 528.81 | C57: 723.89 | D57: 986.54 | E57: 1186.51 | F57: 1106.84 | G57: 589.74 | H57: 315.03 | I57: 72.86 | J57: 286.08 | K57: 1267.01
A58: Other Liabilities | B58: 294.56 | C58: 350.44 | D58: 683.62 | E58: 677.17 | F58: 537.79 | G58: 630.26 | H58: 778.79 | I58: 966.67 | J58: 1012.18 | K58: 1052.64
A59: Total | B59: 1296.24 | C59: 1789.19 | D59: 2592.3 | E59: 2935.27 | F59: 3216.54 | G59: 3566.65 | H59: 4432.26 | I59: 5129.49 | J59: 6094.88 | K59: 7708.32
A60: Net Block | B60: 593.75 | C60: 585.93 | D60: 587.56 | E60: 1715.83 | F60: 1831.98 | G60: 1863.74 | H60: 1963.43 | I60: 1941.61 | J60: 2292.72 | K60: 2457.23
A61: Capital Work in Progress | B61: 35.91 | C61: 349.19 | D61: 954.51 | E61: 33.87 | F61: 172.27 | G61: 220.44 | H61: 122.23 | I61: 300.83 | J61: 773.51 | K61: 1649.05
A62: Investments | B62: 86.6 | C62: 118.08 | D62: 31.77 | E62: 2.39 | F62: 2.38 | G62: 189.29 | H62: 439.02 | I62: 379.35 | J62: 121.85 | K62: 510.89
...

Sheet INCOME STATEMENT
B2: INCOME STATEMENT AND ANALYSIS | I2: *In Crore Rupees
A4: YEARS | B4: 2016 | C4: 2017 | D4: 2018 | E4: 2019 | F4: 2020 | G4: 2021 | H4: 2022 | I4: 2023 | J4: 2024 | K4: 2025 | L4: Trailing | M4: Best | N4: Worst
A5: Revenue | B5: ='Data Sheet'!B15 -> 1372.93 | C5: ='Data Sheet'!C15 -> 1370.71 | D5: ='Data Sheet'!D15 -> 1651.45 | E5: ='Data Sheet'!E15 -> 2699.92 | F5: ='Data Sheet'!F15 -> 4229.71 | G5: ='Data Sheet'!G15 -> 4359.75 | H5: ='Data Sheet'!H15 -> 6802.19 | I5: ='Data Sheet'!I15 -> 7972.06 | ... K5: ='Data Sheet'!K15 -> 8281.93 | L5: =SUM(Quarters[[#This Row],[Column8]:[Column11]]) -> 7874.86 | M5: =K5+M26*K5 -> 8928.9095 | N5: =K5+K5*N26 -> 8843.5334
A6: Expense | B6: =SUM('Data Sheet'!B16,'Data Sheet'!B18:B22,-1*'Data Sheet'!B17) -> 1204.37 | C6: =SUM('Data Sheet'!C16,'Data Sheet'!C18:C22,-1*'Data Sheet'!C17) -> 1231.22 | D6: =SUM('Data Sheet'!D16,'Data Sheet'!D18:D22,-1*'Data Sheet'!D17) -> 1447.4 | E6: =SUM('Data Sheet'!E16,'Data Sheet'!E18:E22,-1*'Data Sheet'!E17) -> 2278.44 | F6: =SUM('Data Sheet'!F16,'Data Sheet'!F18:F22,-1*'Data Sheet'!F17) -> 3194.48 | G6: =SUM('Data Sheet'!G16,'Data Sheet'!G18:G22,-1*'Data Sheet'!G17) -> 3107.73 | H6: =SUM('Data Sheet'!H16,'Data Sheet'!H18:H22,-1*'Data Sheet'!H17) -> 5195.52 | I6: =SUM('Data Sheet'!I16,'Data Sheet'!I18:I22,-1*'Data Sheet'!I17) -> 6679.63 | ... K6: =SUM('Data Sheet'!K16,'Data Sheet'!K18:K22,-1*'Data Sheet'!K17) -> 7186.87 | L6: =SUM(Quarters[[#This Row],[Column8]:[Column11]]) -> 6995.98 | M6: =M5-M7 -> 7651.4211 | N6: =N5-N7 -> 7866.5653
A7: Op. Profit | B7: =B5-B6 -> 168.56 | C7: =C5-C6 -> 139.49 | D7: =D5-D6 -> 204.05 | E7: =E5-E6 -> 421.48 | F7: =F5-F6 -> 1035.23 | G7: =G5-G6 -> 1252.02 | H7: =H5-H6 -> 1606.67 | I7: =I5-I6 -> 1292.43 | ... K7: =K5-K6 -> 1095.06 | L7: =SUM(Quarters[[#This Row],[Column8]:[Column11]]) -> 878.88 | M7: =K7+K7*M27 -> 1277.4884 | N7: =L7+L7*N27 -> 976.9681
A8: Other Income | B8: ='Data Sheet'!B23 -> -0.18 | C8: ='Data Sheet'!C23 -> 79.65 | D8: ='Data Sheet'!D23 -> 6.82 | E8: ='Data Sheet'!E23 -> 10.84 | F8: ='Data Sheet'!F23 -> 28.87 | G8: ='Data Sheet'!G23 -> 19.66 | H8: ='Data Sheet'!H23 -> 41.85 | I8: ='Data Sheet'!I23 -> 46.43 | ... K8: ='Data Sheet'!K23 -> 83.86 | L8: =SUM(Quarters[[#This Row],[Column8]:[Column11]]) -> 88.29
A9: Depreciation | B9: ='Data Sheet'!B24 -> 39.54 | C9: ='Data Sheet'!C24 -> 48.04 | D9: ='Data Sheet'!D24 -> 52.6 | E9: ='Data Sheet'!E24 -> 77.79 | F9: ='Data Sheet'!F24 -> 139.73 | G9: ='Data Sheet'!G24 -> 152.63 | H9: ='Data Sheet'!H24 -> 177.7 | I9: ='Data Sheet'!I24 -> 166.3 | ... K9: ='Data Sheet'!K24 -> 195.37 | L9: =SUM(Quarters[[#This Row],[Column8]:[Column11]]) -> 203.97 | M9: =SUM(Quarters[[#This Row],[Column8]:[Column11]]) -> 203.97 | N9: =SUM(Quarters[[#This Row],[Column8]:[Column11]]) -> 203.97
A10: EBIT | B10: =B12+B11 -> 128.84 | C10: =C12+C11 -> 171.1 | D10: =D12+D11 -> 158.27 | E10: =E12+E11 -> 354.53 | F10: =F12+F11 -> 924.37 | G10: =G12+G11 -> 1119.05 | H10: =H12+H11 -> 1470.82 | I10: =I12+I11 -> 1172.56 | ... N10: =N12+N11 -> 772.9981
A11: Interest | B11: ='Data Sheet'!B25 -> 39.71 | C11: ='Data Sheet'!C25 -> 36.54 | D11: ='Data Sheet'!D25 -> 47.42 | E11: ='Data Sheet'!E25 -> 86.55 | F11: ='Data Sheet'!F25 -> 117.97 | G11: ='Data Sheet'!G25 -> 77.33 | H11: ='Data Sheet'!H25 -> 36.37 | I11: ='Data Sheet'!I25 -> 26.68 | ... K11: ='Data Sheet'!K25 -> 30.8 | L11: =SUM(Quarters!H10:K10) -> 31.52 | M11: 31.52 | N11: 31.52
A12: Profit before tax | B12: ='Data Sheet'!B26 -> 89.13 | C12: ='Data Sheet'!C26 -> 134.56 | D12: ='Data Sheet'!D26 -> 110.85 | E12: ='Data Sheet'!E26 -> 267.98 | F12: ='Data Sheet'!F26 -> 806.4 | G12: ='Data Sheet'!G26 -> 1041.72 | H12: ='Data Sheet'!H26 -> 1434.45 | I12: ='Data Sheet'!I26 -> 1145.88 | ... K12: ='Data Sheet'!K26 -> 952.75 | L12: =SUM(Quarters!H11:K11) -> 731.68 | M12: =M7-M9-M11 -> 1041.9984 | N12: =N7-N9-N11 -> 741.4781
A13: Tax | B13: ='Data Sheet'!B27 -> 26.23 | C13: ='Data Sheet'!C27 -> 38.24 | D13: ='Data Sheet'!D27 -> 31.84 | E13: ='Data Sheet'!E27 -> 94.32 | F13: ='Data Sheet'!F27 -> 195.37 | G13: ='Data Sheet'!G27 -> 265.91 | H13: ='Data Sheet'!H27 -> 367.81 | I13: ='Data Sheet'!I27 -> 293.88 | ... K13: ='Data Sheet'!K27 -> 255.38 | L13: =SUM(Quarters!H12:K12) -> 200.05 | M13: =K13/K12*M12 -> 279.30259 | N13: =L13/L12*N12 -> 202.72892
A14: Net profit | B14: ='Data Sheet'!B28 -> 62.73 | C14: ='Data Sheet'!C28 -> 96.32 | D14: ='Data Sheet'!D28 -> 79.02 | E14: ='Data Sheet'!E28 -> 173.66 | F14: ='Data Sheet'!F28 -> 611.03 | G14: ='Data Sheet'!G28 -> 775.81 | H14: ='Data Sheet'!H28 -> 1066.64 | I14: ='Data Sheet'!I28 -> 852 | ... K14: ='Data Sheet'!K28 -> 697.24 | L14: =SUM(Quarters!H13:K13) -> 531.41 | M14: =M12-M13 -> 762.69577 | N14: =N12-N13 -> 538.74918
A15: EPS | B15: =B14/'Data Sheet'!B91 -> 5.3938091 | C15: =C14/'Data Sheet'!C91 -> 7.3695486 | D15: =D14/'Data Sheet'!D91 -> 5.7932551 | E15: =E14/'Data Sheet'!E91 -> 12.731672 | F15: =F14/'Data Sheet'!F91 -> 44.796921 | G15: =G14/'Data Sheet'!G91 -> 56.877566 | H15: =H14/'Data Sheet'!H91 -> 78.199413 | I15: =I14/'Data Sheet'!I91 -> 62.463343 | ... K15: =K14/'Data Sheet'!K91 -> 51.117302 | L15: =L14/'Data Sheet'!$B$4 -> 38.961699 | M15: =M14/'Data Sheet'!$B$4 -> 55.919013 | N15: =N14/'Data Sheet'!$B$4 -> 39.49979
A16: PE Ratio | B16: =B17/B15 -> 12.607046 | C16: =C17/C15 -> 17.809775 | D16: =D17/D15 -> 42.791141 | E16: =E17/E15 -> 21.532915 | F16: =F17/F15 -> 8.5954569 | G16: =G17/G15 -> 29.123961 | H16: =H17/H15 -> 28.69267 | I16: =I17/I15 -> 29.498901 | ... L16: =L17/L15 -> 43.379782 | M16: =M28 -> 43.379782 | N16: =N28 -> 26.520938
A17: Market Price(Rs.) | B17: ='Data Sheet'!B88 -> 68 | C17: ='Data Sheet'!C88 -> 131.25 | D17: ='Data Sheet'!D88 -> 247.9 | E17: ='Data Sheet'!E88 -> 274.15 | F17: ='Data Sheet'!F88 -> 385.05 | G17: ='Data Sheet'!G88 -> 1656.5 | H17: ='Data Sheet'!H88 -> 2243.75 | I17: ='Data Sheet'!I88 -> 1842.6 | ... K17: ='Data Sheet'!K88 -> 1983.6 | L17: ='Data Sheet'!B6 -> 1690.15 | M17: =M15*M16 -> 2425.7546 | N17: =N15*N16 -> 1047.5715
A18: Dividend | B18: ='Data Sheet'!B29 -> 13.96 | C18: ='Data Sheet'!C29 -> 15.68 | D18: ='Data Sheet'!D29 -> 17.73 | E18: ='Data Sheet'!E29 -> 27.28 | F18: ='Data Sheet'!F29 -> 61.38 | G18: ='Data Sheet'!G29 -> 75.02 | H18: ='Data Sheet'!H29 -> 95.48 | I18: ='Data Sheet'!I29 -> 102.3 | ... K18: ='Data Sheet'!K29 -> 102.3
A20: RATIOS
A21: Dividend Payout | B21: =B18/B14 -> 0.22254105 | C21: =C18/C14 -> 0.1627907 | D21: =D18/D14 -> 0.22437358 | E21: =E18/E14 -> 0.15708856 | F21: =F18/F14 -> 0.10045333 | G21: =G18/G14 -> 0.096698934 | H21: =H18/H14 -> 0.089514738 | I21: =I18/I14 -> 0.12007042 | ... K21: =K18/K14 -> 0.14672136
A22: OPM | B22: =B7/B5 -> 0.12277392 | C22: =C7/C5 -> 0.10176478 | D22: =D7/D5 -> 0.12355809 | E22: =E7/E5 -> 0.15610833 | F22: =F7/F5 -> 0.244752 | G22: =G7/G5 -> 0.28717702 | H22: =H7/H5 -> 0.23619893 | I22: =I7/I5 -> 0.16211995 | ... L22: =L7/L5 -> 0.11160579
G25: TRENDS | H25: 9 Years | I25: 7 Years | J25: 5 Years | K25: 3 Years | L25: Recent | M25: Best | N25: Worst
G26: Sales Growth | H26: =(K5/B5)^(1/9)-1 -> 0.22101318 | I26: =(K5/D5)^(1/7)-1 -> 0.25903562 | J26: =(K5/F5)^(1/5)-1 -> 0.14383714 | K26: =(K5/H5)^(1/3)-1 -> 0.067810693 | L26: =K5/J5-1 -> 0.078119406 | M26: =MAX(K26:L26) -> 0.078119406 | N26: =MIN(H26:L26) -> 0.067810693
G27: OPM | H27: =SUMPRODUCT(B5:K5,B22:$K$22)/SUM(B5:$K$5) -> 0.17968751 | I27: =SUMPRODUCT(D5:K5,D22:$K$22)/SUM(D5:$K$5) -> 0.18392178 | J27: =SUMPRODUCT(F5:K5,F22:$K$22)/SUM(F5:$K$5) -> 0.18836605 | K27: =SUMPRODUCT(H5:K5,H22:$K$22)/SUM(H5:$K$5) -> 0.16659211 | L27: =L22 -> 0.11160579 | M27: =MAX(K27:L27) -> 0.16659211 | N27: =MIN(H27:L27) -> 0.11160579
G28: PE RATIO | H28: =AVERAGE(B16:K16) -> 26.520938 | I28: =AVERAGE(D16:K16) -> 29.349069 | J28: =AVERAGE(F16:K16) -> 28.411417 | K28: =AVERAGE(H16:K16) -> 33.18727 | L28: =L16 -> 43.379782 | M28: =MAX(K28:L28) -> 43.379782 | N28: =MIN(H28:L28) -> 26.520938

Sheet Quarters
A2: Quarters | D2: *In Crore Rupees
A4: Narration | B4: ='Data Sheet'!B39 -> 45107 | C4: ='Data Sheet'!C39 -> 45199 | D4: ='Data Sheet'!D39 -> 45291 | E4: ='Data Sheet'!E39 -> 45382 | F4: ='Data Sheet'!F39 -> 45473 | G4: ='Data Sheet'!G39 -> 45565 | H4: ='Data Sheet'!H39 -> 45657 | I4: ='Data Sheet'!I39 -> 45747 | ... K4: ='Data Sheet'!K39 -> 45930
A5: Sales | B5: ='Data Sheet'!B40 -> 1768.34 | C5: ='Data Sheet'!C40 -> 1778.05 | D5: ='Data Sheet'!D40 -> 2009.23 | E5: ='Data Sheet'!E40 -> 2126.21 | F5: ='Data Sheet'!F40 -> 2166.84 | G5: ='Data Sheet'!G40 -> 2032 | H5: ='Data Sheet'!H40 -> 1903.4 | I5: ='Data Sheet'!I40 -> 2179.69 | ... K5: ='Data Sheet'!K40 -> 1901.89
A6: Expenses | B6: ='Data Sheet'!B41 -> 1558.59 | C6: ='Data Sheet'!C41 -> 1475.79 | D6: ='Data Sheet'!D41 -> 1704.58 | E6: ='Data Sheet'!E41 -> 1825.09 | F6: ='Data Sheet'!F41 -> 1857.65 | G6: ='Data Sheet'!G41 -> 1734.48 | H6: ='Data Sheet'!H41 -> 1734.86 | I6: ='Data Sheet'!I41 -> 1863.18 | ... K6: ='Data Sheet'!K41 -> 1697.62
A7: Operating Profit | B7: ='Data Sheet'!B48 -> 209.75 | C7: ='Data Sheet'!C48 -> 302.26 | D7: ='Data Sheet'!D48 -> 304.65 | E7: ='Data Sheet'!E48 -> 301.12 | F7: ='Data Sheet'!F48 -> 309.19 | G7: ='Data Sheet'!G48 -> 297.52 | H7: ='Data Sheet'!H48 -> 168.54 | I7: ='Data Sheet'!I48 -> 316.51 | ... K7: ='Data Sheet'!K48 -> 204.27
A8: Other Income | B8: ='Data Sheet'!B42 -> 31.87 | C8: ='Data Sheet'!C42 -> 17.05 | D8: ='Data Sheet'!D42 -> 13.56 | E8: ='Data Sheet'!E42 -> 98.94 | F8: ='Data Sheet'!F42 -> 18.81 | G8: ='Data Sheet'!G42 -> 21.27 | H8: ='Data Sheet'!H42 -> 20.99 | I8: ='Data Sheet'!I42 -> 22.79 | ... K8: ='Data Sheet'!K42 -> 19.95
A9: Depreciation | B9: ='Data Sheet'!B43 -> 38.08 | C9: ='Data Sheet'!C43 -> 39.43 | D9: ='Data Sheet'!D43 -> 41.69 | E9: ='Data Sheet'!E43 -> 46.46 | F9: ='Data Sheet'!F43 -> 47.45 | G9: ='Data Sheet'!G43 -> 48.46 | H9: ='Data Sheet'!H43 -> 48.22 | I9: ='Data Sheet'!I43 -> 51.25 | ... K9: ='Data Sheet'!K43 -> 53.25
A10: Interest | B10: ='Data Sheet'!B44 -> 1.81 | C10: ='Data Sheet'!C44 -> 2.68 | D10: ='Data Sheet'!D44 -> 2.93 | E10: ='Data Sheet'!E44 -> 4.41 | F10: ='Data Sheet'!F44 -> 5.75 | G10: ='Data Sheet'!G44 -> 6.3 | H10: ='Data Sheet'!H44 -> 6.11 | I10: ='Data Sheet'!I44 -> 9.34 | ... K10: ='Data Sheet'!K44 -> 7.94
A11: Profit before tax | B11: ='Data Sheet'!B45 -> 201.73 | C11: ='Data Sheet'!C45 -> 277.2 | D11: ='Data Sheet'!D45 -> 273.59 | E11: ='Data Sheet'!E45 -> 349.19 | F11: ='Data Sheet'!F45 -> 274.8 | G11: ='Data Sheet'!G45 -> 264.03 | H11: ='Data Sheet'!H45 -> 135.2 | I11: ='Data Sheet'!I45 -> 278.71 | ... K11: ='Data Sheet'!K45 -> 163.03
A12: Tax | B12: ='Data Sheet'!B46 -> 51.83 | C12: ='Data Sheet'!C46 -> 72.12 | D12: ='Data Sheet'!D46 -> 71.54 | E12: ='Data Sheet'!E46 -> 95.34 | F12: ='Data Sheet'!F46 -> 72.27 | G12: ='Data Sheet'!G46 -> 69.83 | H12: ='Data Sheet'!H46 -> 37.07 | I12: ='Data Sheet'!I46 -> 76.21 | ... K12: ='Data Sheet'!K46 -> 44.28
A13: Net profit | B13: ='Data Sheet'!B47 -> 149.9 | C13: ='Data Sheet'!C47 -> 205.08 | D13: ='Data Sheet'!D47 -> 202.05 | E13: ='Data Sheet'!E47 -> 253.86 | F13: ='Data Sheet'!F47 -> 202.54 | G13: ='Data Sheet'!G47 -> 194.19 | H13: ='Data Sheet'!H47 -> 98.09 | I13: ='Data Sheet'!I47 -> 202.41 | ... K13: ='Data Sheet'!K47 -> 118.71
A15: OPM | B15: =IF(B5>0,B7/B5,"") -> 0.11861407 | C15: =IF(C5>0,C7/C5,"") -> 0.16999522 | D15: =IF(D5>0,D7/D5,"") -> 0.15162525 | E15: =IF(E5>0,E7/E5,"") -> 0.14162289 | F15: =IF(F5>0,F7/F5,"") -> 0.14269166 | G15: =IF(G5>0,G7/G5,"") -> 0.14641732 | H15: =IF(H5>0,H7/H5,"") -> 0.088546811 | I15: =IF(I5>0,I7/I5,"") -> 0.14520872 | ... K15: =IF(K5>0,K7/K5,"") -> 0.10740369

Sheet Balance Sheet
E2: BALANCE SHEET | I2: *In Crore Rupees
A4: Narration | B4: ='Data Sheet'!B54 -> 42460 | C4: ='Data Sheet'!C54 -> 42825 | D4: ='Data Sheet'!D54 -> 43190 | E4: ='Data Sheet'!E54 -> 43555 | F4: ='Data Sheet'!F54 -> 43921 | G4: ='Data Sheet'!G54 -> 44286 | H4: ='Data Sheet'!H54 -> 44651 | I4: ='Data Sheet'!I54 -> 45016 | ... K4: ='Data Sheet'!K54 -> 45747
A5: Equity Share Capital | B5: ='Data Sheet'!B55 -> 23.26 | C5: ='Data Sheet'!C55 -> 26.14 | D5: ='Data Sheet'!D55 -> 27.28 | E5: ='Data Sheet'!E55 -> 27.28 | F5: ='Data Sheet'!F55 -> 27.28 | G5: ='Data Sheet'!G55 -> 27.28 | H5: ='Data Sheet'!H55 -> 27.28 | I5: ='Data Sheet'!I55 -> 27.28 | ... K5: ='Data Sheet'!K55 -> 27.28
A6: Reserves | B6: ='Data Sheet'!B56 -> 449.61 | C6: ='Data Sheet'!C56 -> 688.72 | D6: ='Data Sheet'!D56 -> 894.86 | E6: ='Data Sheet'!E56 -> 1044.31 | F6: ='Data Sheet'!F56 -> 1544.63 | G6: ='Data Sheet'!G56 -> 2319.37 | H6: ='Data Sheet'!H56 -> 3311.16 | I6: ='Data Sheet'!I56 -> 4062.68 | ... K6: ='Data Sheet'!K56 -> 5361.39
A7: Borrowings | B7: ='Data Sheet'!B57 -> 528.81 | C7: ='Data Sheet'!C57 -> 723.89 | D7: ='Data Sheet'!D57 -> 986.54 | E7: ='Data Sheet'!E57 -> 1186.51 | F7: ='Data Sheet'!F57 -> 1106.84 | G7: ='Data Sheet'!G57 -> 589.74 | H7: ='Data Sheet'!H57 -> 315.03 | I7: ='Data Sheet'!I57 -> 72.86 | ... K7: ='Data Sheet'!K57 -> 1267.01
A8: Other Liabilities | B8: ='Data Sheet'!B58 -> 294.56 | C8: ='Data Sheet'!C58 -> 350.44 | D8: ='Data Sheet'!D58 -> 683.62 | E8: ='Data Sheet'!E58 -> 677.17 | F8: ='Data Sheet'!F58 -> 537.79 | G8: ='Data Sheet'!G58 -> 630.26 | H8: ='Data Sheet'!H58 -> 778.79 | I8: ='Data Sheet'!I58 -> 966.67 | ... K8: ='Data Sheet'!K58 -> 1052.64
A9: Total | B9: ='Data Sheet'!B59 -> 1296.24 | C9: ='Data Sheet'!C59 -> 1789.19 | D9: ='Data Sheet'!D59 -> 2592.3 | E9: ='Data Sheet'!E59 -> 2935.27 | F9: ='Data Sheet'!F59 -> 3216.54 | G9: ='Data Sheet'!G59 -> 3566.65 | H9: ='Data Sheet'!H59 -> 4432.26 | I9: ='Data Sheet'!I59 -> 5129.49 | ... K9: ='Data Sheet'!K59 -> 7708.32
A11: Net Block | B11: ='Data Sheet'!B60 -> 593.75 | C11: ='Data Sheet'!C60 -> 585.93 | D11: ='Data Sheet'!D60 -> 587.56 | E11: ='Data Sheet'!E60 -> 1715.83 | F11: ='Data Sheet'!F60 -> 1831.98 | G11: ='Data Sheet'!G60 -> 1863.74 | H11: ='Data Sheet'!H60 -> 1963.43 | I11: ='Data Sheet'!I60 -> 1941.61 | ... K11: ='Data Sheet'!K60 -> 2457.23
A12: Capital Work in Progress | B12: ='Data Sheet'!B61 -> 35.91 | C12: ='Data Sheet'!C61 -> 349.19 | D12: ='Data Sheet'!D61 -> 954.51 | E12: ='Data Sheet'!E61 -> 33.87 | F12: ='Data Sheet'!F61 -> 172.27 | G12: ='Data Sheet'!G61 -> 220.44 | H12: ='Data Sheet'!H61 -> 122.23 | I12: ='Data Sheet'!I61 -> 300.83 | ... K12: ='Data Sheet'!K61 -> 1649.05
A13: Investments | B13: ='Data Sheet'!B62 -> 86.6 | C13: ='Data Sheet'!C62 -> 118.08 | D13: ='Data Sheet'!D62 -> 31.77 | E13: ='Data Sheet'!E62 -> 2.39 | F13: ='Data Sheet'!F62 -> 2.38 | G13: ='Data Sheet'!G62 -> 189.29 | H13: ='Data Sheet'!H62 -> 439.02 | I13: ='Data Sheet'!I62 -> 379.35 | ... K13: ='Data Sheet'!K62 -> 510.89
A14: Other Assets | B14: ='Data Sheet'!B63 -> 579.98 | C14: ='Data Sheet'!C63 -> 735.99 | D14: ='Data Sheet'!D63 -> 1018.46 | E14: ='Data Sheet'!E63 -> 1183.18 | F14: ='Data Sheet'!F63 -> 1209.91 | G14: ='Data Sheet'!G63 -> 1293.18 | H14: ='Data Sheet'!H63 -> 1907.58 | I14: ='Data Sheet'!I63 -> 2507.7 | ... K14: ='Data Sheet'!K63 -> 3091.15
A15: Total | B15: ='Data Sheet'!B64 -> 1296.24 | C15: ='Data Sheet'!C64 -> 1789.19 | D15: ='Data Sheet'!D64 -> 2592.3 | E15: ='Data Sheet'!E64 -> 2935.27 | F15: ='Data Sheet'!F64 -> 3216.54 | G15: ='Data Sheet'!G64 -> 3566.65 | H15: ='Data Sheet'!H64 -> 4432.26 | I15: ='Data Sheet'!I64 -> 5129.49 | ... K15: ='Data Sheet'!K64 -> 7708.32
A17: Working Capital | B17: =B14-B8 -> 285.42 | C17: =C14-C8 -> 385.55 | D17: =D14-D8 -> 334.84 | E17: =E14-E8 -> 506.01 | F17: =F14-F8 -> 672.12 | G17: =G14-G8 -> 662.92 | H17: =H14-H8 -> 1128.79 | I17: =I14-I8 -> 1541.03 | ... K17: =K14-K8 -> 2038.51
A18: Debtors | B18: ='Data Sheet'!B65 -> 313.19 | C18: ='Data Sheet'!C65 -> 360.33 | D18: ='Data Sheet'!D65 -> 411.77 | E18: ='Data Sheet'!E65 -> 574.96 | F18: ='Data Sheet'!F65 -> 612.72 | G18: ='Data Sheet'!G65 -> 756.3 | H18: ='Data Sheet'!H65 -> 1129.06 | I18: ='Data Sheet'!I65 -> 1309.52 | ... K18: ='Data Sheet'!K65 -> 1273.81
A19: Inventory | B19: ='Data Sheet'!B66 -> 123.11 | C19: ='Data Sheet'!C66 -> 168.85 | D19: ='Data Sheet'!D66 -> 327.16 | E19: ='Data Sheet'!E66 -> 418.22 | F19: ='Data Sheet'!F66 -> 402.43 | G19: ='Data Sheet'!G66 -> 389.04 | H19: ='Data Sheet'!H66 -> 586.35 | I19: ='Data Sheet'!I66 -> 893.97 | ... K19: ='Data Sheet'!K66 -> 928.7
A21: Debtor Days | B21: =IF('INCOME STATEMENT'!B5>0,'Balance Sheet'!B18/('INCOME STATEMENT'!B5/365),0) -> 83.263058 | C21: =IF('INCOME STATEMENT'!C5>0,'Balance Sheet'!C18/('INCOME STATEMENT'!C5/365),0) -> 95.950602 | D21: =IF('INCOME STATEMENT'!D5>0,'Balance Sheet'!D18/('INCOME STATEMENT'!D5/365),0) -> 91.008538 | E21: =IF('INCOME STATEMENT'!E5>0,'Balance Sheet'!E18/('INCOME STATEMENT'!E5/365),0) -> 77.728377 | F21: =IF('INCOME STATEMENT'!F5>0,'Balance Sheet'!F18/('INCOME STATEMENT'!F5/365),0) -> 52.874263 | G21: =IF('INCOME STATEMENT'!G5>0,'Balance Sheet'!G18/('INCOME STATEMENT'!G5/365),0) -> 63.317736 | H21: =IF('INCOME STATEMENT'!H5>0,'Balance Sheet'!H18/('INCOME STATEMENT'!H5/365),0) -> 60.584444 | I21: =IF('INCOME STATEMENT'!I5>0,'Balance Sheet'!I18/('INCOME STATEMENT'!I5/365),0) -> 59.956247 | ... K21: =IF('INCOME STATEMENT'!K5>0,'Balance Sheet'!K18/('INCOME STATEMENT'!K5/365),0) -> 56.139167
A22: Inventory Turnover | B22: =IF('Balance Sheet'!B19>0,'INCOME STATEMENT'!B5/'Balance Sheet'!B19,0) -> 11.152059 | C22: =IF('Balance Sheet'!C19>0,'INCOME STATEMENT'!C5/'Balance Sheet'!C19,0) -> 8.1179153 | D22: =IF('Balance Sheet'!D19>0,'INCOME STATEMENT'!D5/'Balance Sheet'!D19,0) -> 5.0478359 | E22: =IF('Balance Sheet'!E19>0,'INCOME STATEMENT'!E5/'Balance Sheet'!E19,0) -> 6.455741 | F22: =IF('Balance Sheet'!F19>0,'INCOME STATEMENT'!F5/'Balance Sheet'!F19,0) -> 10.510424 | G22: =IF('Balance Sheet'!G19>0,'INCOME STATEMENT'!G5/'Balance Sheet'!G19,0) -> 11.206431 | H22: =IF('Balance Sheet'!H19>0,'INCOME STATEMENT'!H5/'Balance Sheet'!H19,0) -> 11.600904 | I22: =IF('Balance Sheet'!I19>0,'INCOME STATEMENT'!I5/'Balance Sheet'!I19,0) -> 8.9175923 | ... K22: =IF('Balance Sheet'!K19>0,'INCOME STATEMENT'!K5/'Balance Sheet'!K19,0) -> 8.9177668
A24: Return on Equity | B24: =IF(SUM('Balance Sheet'!B5:B6)>0,'INCOME STATEMENT'!B14/SUM('Balance Sheet'!B5:B6),"") -> 0.13265802 | C24: =IF(SUM('Balance Sheet'!C5:C6)>0,'INCOME STATEMENT'!C14/SUM('Balance Sheet'!C5:C6),"") -> 0.13473967 | D24: =IF(SUM('Balance Sheet'!D5:D6)>0,'INCOME STATEMENT'!D14/SUM('Balance Sheet'!D5:D6),"") -> 0.085691977 | E24: =IF(SUM('Balance Sheet'!E5:E6)>0,'INCOME STATEMENT'!E14/SUM('Balance Sheet'!E5:E6),"") -> 0.16205825 | F24: =IF(SUM('Balance Sheet'!F5:F6)>0,'INCOME STATEMENT'!F14/SUM('Balance Sheet'!F5:F6),"") -> 0.38871818 | G24: =IF(SUM('Balance Sheet'!G5:G6)>0,'INCOME STATEMENT'!G14/SUM('Balance Sheet'!G5:G6),"") -> 0.3306032 | H24: =IF(SUM('Balance Sheet'!H5:H6)>0,'INCOME STATEMENT'!H14/SUM('Balance Sheet'!H5:H6),"") -> 0.31950252 | I24: =IF(SUM('Balance Sheet'!I5:I6)>0,'INCOME STATEMENT'!I14/SUM('Balance Sheet'!I5:I6),"") -> 0.208315 | ... K24: =IF(SUM('Balance Sheet'!K5:K6)>0,'INCOME STATEMENT'!K14/SUM('Balance Sheet'!K5:K6),"") -> 0.12939
A25: Return on Capital Emp | C25: =IF((B5+B6+B7+C5+C6+C7)>0,('INCOME STATEMENT'!C10)*2/(B5+B6+B7+C5+C6+C7),"") -> 0.14022119 | D25: =IF((C5+C6+C7+D5+D6+D7)>0,('INCOME STATEMENT'!D10)*2/(C5+C6+C7+D5+D6+D7),"") -> 0.094562097 | E25: =IF((D5+D6+D7+E5+E6+E7)>0,('INCOME STATEMENT'!E10)*2/(D5+D6+D7+E5+E6+E7),"") -> 0.17016977 | F25: =IF((E5+E6+E7+F5+F6+F7)>0,('INCOME STATEMENT'!F10)*2/(E5+E6+E7+F5+F6+F7),"") -> 0.37447765 | G25: =IF((F5+F6+F7+G5+G6+G7)>0,('INCOME STATEMENT'!G10)*2/(F5+F6+F7+G5+G6+G7),"") -> 0.39858312 | H25: =IF((G5+G6+G7+H5+H6+H7)>0,('INCOME STATEMENT'!H10)*2/(G5+G6+G7+H5+H6+H7),"") -> 0.44638885 | I25: =IF((H5+H6+H7+I5+I6+I7)>0,('INCOME STATEMENT'!I10)*2/(H5+H6+H7+I5+I6+I7),"") -> 0.30002981 | J25: =IF((I5+I6+I7+J5+J6+J7)>0,('INCOME STATEMENT'!J10)*2/(I5+I6+I7+J5+J6+J7),"") -> 0.2415916 | K25: =IF((J5+J6+J7+K5+K6+K7)>0,('INCOME STATEMENT'!K10)*2/(J5+J6+J7+K5+K6+K7),"") -> 0.16757849

Sheet Cash Flow Statement
A1: ='Balance Sheet'!A2 -> 0
A3: Year | B3: ='Data Sheet'!B79 -> 42460 | C3: ='Data Sheet'!C79 -> 42825 | D3: ='Data Sheet'!D79 -> 43190 | E3: ='Data Sheet'!E79 -> 43555 | F3: ='Data Sheet'!F79 -> 43921 | G3: ='Data Sheet'!G79 -> 44286 | H3: ='Data Sheet'!H79 -> 44651 | I3: ='Data Sheet'!I79 -> 45016 | ... K3: ='Data Sheet'!K79 -> 45747
A4: Cash from Operating Activities | B4: ='Data Sheet'!B80 -> 167.28 | C4: ='Data Sheet'!C80 -> 49.01 | D4: ='Data Sheet'!D80 -> 183 | E4: ='Data Sheet'!E80 -> 60.28 | F4: ='Data Sheet'!F80 -> 764.66 | G4: ='Data Sheet'!G80 -> 1001.9 | H4: ='Data Sheet'!H80 -> 823.84 | I4: ='Data Sheet'!I80 -> 649.92 | ... K4: ='Data Sheet'!K80 -> 624.7
A5: Cash from Investing Activities | B5: ='Data Sheet'!B81 -> -169.38 | C5: ='Data Sheet'!C81 -> -352.55 | D5: ='Data Sheet'!D81 -> -524.73 | E5: ='Data Sheet'!E81 -> -162.55 | F5: ='Data Sheet'!F81 -> -427.92 | G5: ='Data Sheet'!G81 -> -396.16 | H5: ='Data Sheet'!H81 -> -424.05 | I5: ='Data Sheet'!I81 -> -276.05 | ... K5: ='Data Sheet'!K81 -> -1489.42
A6: Cash from Financing Activities | B6: ='Data Sheet'!B82 -> 4.33 | C6: ='Data Sheet'!C82 -> 304.62 | D6: ='Data Sheet'!D82 -> 345.31 | E6: ='Data Sheet'!E82 -> 95.81 | F6: ='Data Sheet'!F82 -> -337.56 | G6: ='Data Sheet'!G82 -> -598.99 | H6: ='Data Sheet'!H82 -> -385.83 | I6: ='Data Sheet'!I82 -> -359.08 | ... K6: ='Data Sheet'!K82 -> 806.16
A7: Net Cash Flow | B7: ='Data Sheet'!B83 -> 2.23 | C7: ='Data Sheet'!C83 -> 1.07 | D7: ='Data Sheet'!D83 -> 3.59 | E7: ='Data Sheet'!E83 -> -6.46 | F7: ='Data Sheet'!F83 -> -0.82 | G7: ='Data Sheet'!G83 -> 6.75 | H7: ='Data Sheet'!H83 -> 13.96 | I7: ='Data Sheet'!I83 -> 14.79 | ... K7: ='Data Sheet'!K83 -> -58.56

Sheet Assumptions
B3: Contents | C3: Value (Input) | D3: Note
B4: MACRO INPUTS
B5: Risk Free Rate | C5: 0.07 | D5: India 10Y Bond
B6: Market Risk Premium | C6: 0.06 | D6: Market Return - Risk Free
B7: Beta | C7: 1.2 | D7: Chemical Industry Beta
B8: Cost of Equity (Ke) | C8: =C5+C6*C7 -> 0.142 | D8: Ke = R + β*Rm
B9: Cost of Debt (Pre-Tax) | C9: 0.085 | D9: Interest Rate
B10: Tax Rate | C10: 0.25 | D10: Corporate Tax
B11: WACC | C11: =Valuation!F8 -> 0.12 | D11: Moderate value
B13: OPERATING INPUTS
B14: Revenue Growth (Forecast) | C14: =Valuation!F9 -> 0.12 | D14: Assumption
B15: Terminal Growth Rate | C15: 0.05 | D15: Assumption
B16: EBIT Margin (Forecast) | C16: 0.14 | D16: Assumption

Sheet DCF MODEL
B2: CASH FLOW FORECASTING | F2: *In Crore Rupees
B4: Year | C4: 2025 | D4: 2026 | E4: 2027 | F4: 2028 | G4: 2029 | H4: 2030
B5: Revenue | C5: ='Data Sheet'!K15 -> 8281.93 | D5: =C5*(1+Assumptions!$C$14) -> 9275.7616 | E5: =D5*(1+Assumptions!$C$14) -> 10388.853 | F5: =E5*(1+Assumptions!$C$14) -> 11635.515 | G5: =F5*(1+Assumptions!$C$14) -> 13031.777 | H5: =G5*(1+Assumptions!$C$14) -> 14595.59
B6: EBIT | C6: ='Data Sheet'!K26+'Data Sheet'!K25 -> 983.55 | D6: =D5*(Assumptions!$C$16) -> 1298.6066 | E6: =E5*(Assumptions!$C$16) -> 1454.4394 | F6: =F5*(Assumptions!$C$16) -> 1628.9721 | G6: =G5*(Assumptions!$C$16) -> 1824.4488 | H6: =H5*(Assumptions!$C$16) -> 2043.3827
B7: Tax(@25%) | C7: =C6*0.25 -> 245.8875 | D7: =D6*0.25 -> 324.65166 | E7: =E6*0.25 -> 363.60985 | F7: =F6*0.25 -> 407.24304 | G7: =G6*0.25 -> 456.1122 | H7: =H6*0.25 -> 510.84567
B8: NOPAT | C8: =C6-C7 -> 737.6625 | D8: =D6-D7 -> 973.95497 | E8: =E6-E7 -> 1090.8296 | F8: =F6-F7 -> 1221.7291 | G8: =G6-G7 -> 1368.3366 | H8: =H6-H7 -> 1532.537
B10: Reinvestment (40% assumed) | C10: =C8*0.4 -> 295.065 | D10: =D8*0.4 -> 389.58199 | E10: =E8*0.4 -> 436.33183 | F10: =F8*0.4 -> 488.69164 | G10: =G8*0.4 -> 547.33464 | H10: =H8*0.4 -> 613.0148
B11: FCFF | C11: =C8-C10 -> 442.5975 | D11: =D8-D10 -> 584.37298 | E11: =E8-E10 -> 654.49774 | F11: =F8-F10 -> 733.03747 | G11: =G8-G10 -> 821.00196 | H11: =H8-H10 -> 919.5222
B13: DCF | C13: =C11/(1+Assumptions!$C$11)^(C4-$C$4) -> 442.5975 | D13: =D11/(1+Assumptions!$C$11)^(D4-$C$4) -> 521.76159 | E13: =E11/(1+Assumptions!$C$11)^(E4-$C$4) -> 521.76159 | F13: =F11/(1+Assumptions!$C$11)^(F4-$C$4) -> 521.76159 | G13: =G11/(1+Assumptions!$C$11)^(G4-$C$4) -> 521.76159 | H13: =H11/(1+Assumptions!$C$11)^(H4-$C$4) -> 521.76159

Sheet Valuation
B2: VALUATION | E2: *In Crore Rupees
B4: Sum of PV | C4: =SUM('DCF MODEL'!C13:H13) -> 3051.4055
B5: Terminal Value(TV) | C5: ='DCF MODEL'!H11*(1+Assumptions!C15)/(Assumptions!C11-Assumptions!C15) -> 13792.833
B6: PV of TV | C6: =C5/(1+Assumptions!C11)^5 -> 7826.4239
B7: Enterprise Value | C7: =C4+C6 -> 10877.829
B8: Debt | C8: ='Data Sheet'!K57 -> 1267.01 | E8: WACC | F8: 0.12
B9: Cash | C9: ='Data Sheet'!K67 -> 406.56 | E9: Growth | F9: 0.12
B10: Equity Value | C10: =C7-C8+C9 -> 10017.379
B11: Share outstanding | C11: ='Data Sheet'!K91 -> 13.64
B12: Target Price | C12: =C10/C11 -> 734.41197
B16: SENSTIVITY OF SHARE PRICE FOR DIFFERENT RISK RATES
D18: WACC
C19: Target Value | D19: =C12 -> 734.41197 | E19: 0.1 | F19: 0.11 | G19: 0.12 | H19: 0.13 | I19: 0.14 | J19: 0.15
C20: Growth Rate | D20: 0.1 | E20: 963.92587 | F20: 795.31979 | G20: 674.97304 | H20: 584.7849 | I20: 514.69959 | J20: 458.6838
D21: 0.12 | E21: 1050.3461 | F21: 865.97659 | G21: 734.41197 | H21: 635.84526 | I21: 559.27284 | J21: 498.09273
D22: 0.14 | E22: 1142.9002 | F22: 941.60607 | G22: 797.99879 | H22: 690.43873 | I22: 606.90425 | J22: 540.18265
D23: 0.16 | E23: 1241.9154 | F23: 1022.4725 | G23: 865.95295 | H23: 748.75143 | I23: 657.75424 | J23: 585.09358
D24: 0.18 | E24: 1347.7306 | F24: 1108.8493 | G24: 938.50159 | H24: 810.97597 | I24: 711.98881 | J24: 632.9704
D25: 0.2 | E25: 1460.6965 | F25: 1201.0195 | G25: 1015.8797 | H25: 877.31162 | I25: 769.77963 | J25: 683.96295
